Creating test database for alias 'default'...
.................E.EEEEEEEEE..
======================================================================
ERROR: test_integrativo_si_cuenta_tiene_cuenta_madre_registra_saldo_en_fecha_en_cuenta_madre (tests.diario.test_models.test_saldo.TestSaldoMetodoRegistrar)
----------------------------------------------------------------------
Traceback (most recent call last):
  File "/home/nando/prog/finper/tests/diario/test_models/test_saldo.py", line 329, in test_integrativo_si_cuenta_tiene_cuenta_madre_registra_saldo_en_fecha_en_cuenta_madre
    Saldo.registrar(sc1, date(2010, 11, 11), 30)
  File "/home/nando/prog/finper/diario/models/saldo.py", line 86, in registrar
    saldo = super().tomar(cuenta=cuenta, fecha=fecha)
  File "/home/nando/prog/finper/vvmodel/models.py", line 29, in tomar
    return cls.objects.db_manager(using).get(**kwargs)
  File "/home/nando/prog/finper/vfinper/lib/python3.8/site-packages/django/db/models/manager.py", line 85, in manager_method
    return getattr(self.get_queryset(), name)(*args, **kwargs)
  File "/home/nando/prog/finper/vfinper/lib/python3.8/site-packages/django/db/models/query.py", line 424, in get
    clone = self._chain() if self.query.combinator else self.filter(*args, **kwargs)
  File "/home/nando/prog/finper/vfinper/lib/python3.8/site-packages/django/db/models/query.py", line 941, in filter
    return self._filter_or_exclude(False, args, kwargs)
  File "/home/nando/prog/finper/vfinper/lib/python3.8/site-packages/django/db/models/query.py", line 961, in _filter_or_exclude
    clone._filter_or_exclude_inplace(negate, args, kwargs)
  File "/home/nando/prog/finper/vfinper/lib/python3.8/site-packages/django/db/models/query.py", line 968, in _filter_or_exclude_inplace
    self._query.add_q(Q(*args, **kwargs))
  File "/home/nando/prog/finper/vfinper/lib/python3.8/site-packages/django/db/models/sql/query.py", line 1396, in add_q
    clause, _ = self._add_q(q_object, self.used_aliases)
  File "/home/nando/prog/finper/vfinper/lib/python3.8/site-packages/django/db/models/sql/query.py", line 1415, in _add_q
    child_clause, needed_inner = self.build_filter(
  File "/home/nando/prog/finper/vfinper/lib/python3.8/site-packages/django/db/models/sql/query.py", line 1289, in build_filter
    lookups, parts, reffed_expression = self.solve_lookup_type(arg)
  File "/home/nando/prog/finper/vfinper/lib/python3.8/site-packages/django/db/models/sql/query.py", line 1115, in solve_lookup_type
    _, field, _, lookup_parts = self.names_to_path(lookup_splitted, self.get_meta())
  File "/home/nando/prog/finper/vfinper/lib/python3.8/site-packages/django/db/models/sql/query.py", line 1542, in names_to_path
    raise FieldError("Cannot resolve keyword '%s' into field. "
django.core.exceptions.FieldError: Cannot resolve keyword 'fecha' into field. Choices are: cuenta, cuenta_id, id, importe, movimiento, movimiento_id

======================================================================
ERROR: test_primer_registro_en_fecha_genera_nuevo_saldo (tests.diario.test_models.test_saldo.TestSaldoMetodoRegistrar)
----------------------------------------------------------------------
Traceback (most recent call last):
  File "/usr/lib/python3.8/unittest/mock.py", line 1325, in patched
    return func(*newargs, **newkeywargs)
  File "/home/nando/prog/finper/tests/diario/test_models/test_saldo.py", line 215, in test_primer_registro_en_fecha_genera_nuevo_saldo
    Saldo.registrar(self.cuenta, date(2010, 11, 11), 100)
  File "/home/nando/prog/finper/diario/models/saldo.py", line 86, in registrar
    saldo = super().tomar(cuenta=cuenta, fecha=fecha)
  File "/home/nando/prog/finper/vvmodel/models.py", line 29, in tomar
    return cls.objects.db_manager(using).get(**kwargs)
  File "/home/nando/prog/finper/vfinper/lib/python3.8/site-packages/django/db/models/manager.py", line 85, in manager_method
    return getattr(self.get_queryset(), name)(*args, **kwargs)
  File "/home/nando/prog/finper/vfinper/lib/python3.8/site-packages/django/db/models/query.py", line 424, in get
    clone = self._chain() if self.query.combinator else self.filter(*args, **kwargs)
  File "/home/nando/prog/finper/vfinper/lib/python3.8/site-packages/django/db/models/query.py", line 941, in filter
    return self._filter_or_exclude(False, args, kwargs)
  File "/home/nando/prog/finper/vfinper/lib/python3.8/site-packages/django/db/models/query.py", line 961, in _filter_or_exclude
    clone._filter_or_exclude_inplace(negate, args, kwargs)
  File "/home/nando/prog/finper/vfinper/lib/python3.8/site-packages/django/db/models/query.py", line 968, in _filter_or_exclude_inplace
    self._query.add_q(Q(*args, **kwargs))
  File "/home/nando/prog/finper/vfinper/lib/python3.8/site-packages/django/db/models/sql/query.py", line 1396, in add_q
    clause, _ = self._add_q(q_object, self.used_aliases)
  File "/home/nando/prog/finper/vfinper/lib/python3.8/site-packages/django/db/models/sql/query.py", line 1415, in _add_q
    child_clause, needed_inner = self.build_filter(
  File "/home/nando/prog/finper/vfinper/lib/python3.8/site-packages/django/db/models/sql/query.py", line 1289, in build_filter
    lookups, parts, reffed_expression = self.solve_lookup_type(arg)
  File "/home/nando/prog/finper/vfinper/lib/python3.8/site-packages/django/db/models/sql/query.py", line 1115, in solve_lookup_type
    _, field, _, lookup_parts = self.names_to_path(lookup_splitted, self.get_meta())
  File "/home/nando/prog/finper/vfinper/lib/python3.8/site-packages/django/db/models/sql/query.py", line 1542, in names_to_path
    raise FieldError("Cannot resolve keyword '%s' into field. "
django.core.exceptions.FieldError: Cannot resolve keyword 'fecha' into field. Choices are: cuenta, cuenta_id, id, importe, movimiento, movimiento_id

======================================================================
ERROR: test_saldo_creado_suma_importe_recibido_a_ultimo_saldo_anterior_de_cuenta (tests.diario.test_models.test_saldo.TestSaldoMetodoRegistrar)
----------------------------------------------------------------------
Traceback (most recent call last):
  File "/home/nando/prog/finper/tests/diario/test_models/test_saldo.py", line 223, in test_saldo_creado_suma_importe_recibido_a_ultimo_saldo_anterior_de_cuenta
    Saldo.registrar(self.cuenta, date(2010, 11, 1), 100)
  File "/home/nando/prog/finper/diario/models/saldo.py", line 86, in registrar
    saldo = super().tomar(cuenta=cuenta, fecha=fecha)
  File "/home/nando/prog/finper/vvmodel/models.py", line 29, in tomar
    return cls.objects.db_manager(using).get(**kwargs)
  File "/home/nando/prog/finper/vfinper/lib/python3.8/site-packages/django/db/models/manager.py", line 85, in manager_method
    return getattr(self.get_queryset(), name)(*args, **kwargs)
  File "/home/nando/prog/finper/vfinper/lib/python3.8/site-packages/django/db/models/query.py", line 424, in get
    clone = self._chain() if self.query.combinator else self.filter(*args, **kwargs)
  File "/home/nando/prog/finper/vfinper/lib/python3.8/site-packages/django/db/models/query.py", line 941, in filter
    return self._filter_or_exclude(False, args, kwargs)
  File "/home/nando/prog/finper/vfinper/lib/python3.8/site-packages/django/db/models/query.py", line 961, in _filter_or_exclude
    clone._filter_or_exclude_inplace(negate, args, kwargs)
  File "/home/nando/prog/finper/vfinper/lib/python3.8/site-packages/django/db/models/query.py", line 968, in _filter_or_exclude_inplace
    self._query.add_q(Q(*args, **kwargs))
  File "/home/nando/prog/finper/vfinper/lib/python3.8/site-packages/django/db/models/sql/query.py", line 1396, in add_q
    clause, _ = self._add_q(q_object, self.used_aliases)
  File "/home/nando/prog/finper/vfinper/lib/python3.8/site-packages/django/db/models/sql/query.py", line 1415, in _add_q
    child_clause, needed_inner = self.build_filter(
  File "/home/nando/prog/finper/vfinper/lib/python3.8/site-packages/django/db/models/sql/query.py", line 1289, in build_filter
    lookups, parts, reffed_expression = self.solve_lookup_type(arg)
  File "/home/nando/prog/finper/vfinper/lib/python3.8/site-packages/django/db/models/sql/query.py", line 1115, in solve_lookup_type
    _, field, _, lookup_parts = self.names_to_path(lookup_splitted, self.get_meta())
  File "/home/nando/prog/finper/vfinper/lib/python3.8/site-packages/django/db/models/sql/query.py", line 1542, in names_to_path
    raise FieldError("Cannot resolve keyword '%s' into field. "
django.core.exceptions.FieldError: Cannot resolve keyword 'fecha' into field. Choices are: cuenta, cuenta_id, id, importe, movimiento, movimiento_id

======================================================================
ERROR: test_saldo_registrado_en_fecha_antigua_modifica_saldos_de_fechas_posteriores (tests.diario.test_models.test_saldo.TestSaldoMetodoRegistrar)
----------------------------------------------------------------------
Traceback (most recent call last):
  File "/home/nando/prog/finper/tests/diario/test_models/test_saldo.py", line 273, in test_saldo_registrado_en_fecha_antigua_modifica_saldos_de_fechas_posteriores
    Saldo.registrar(self.cuenta, date(2010, 11, 15), 20)
  File "/home/nando/prog/finper/diario/models/saldo.py", line 86, in registrar
    saldo = super().tomar(cuenta=cuenta, fecha=fecha)
  File "/home/nando/prog/finper/vvmodel/models.py", line 29, in tomar
    return cls.objects.db_manager(using).get(**kwargs)
  File "/home/nando/prog/finper/vfinper/lib/python3.8/site-packages/django/db/models/manager.py", line 85, in manager_method
    return getattr(self.get_queryset(), name)(*args, **kwargs)
  File "/home/nando/prog/finper/vfinper/lib/python3.8/site-packages/django/db/models/query.py", line 424, in get
    clone = self._chain() if self.query.combinator else self.filter(*args, **kwargs)
  File "/home/nando/prog/finper/vfinper/lib/python3.8/site-packages/django/db/models/query.py", line 941, in filter
    return self._filter_or_exclude(False, args, kwargs)
  File "/home/nando/prog/finper/vfinper/lib/python3.8/site-packages/django/db/models/query.py", line 961, in _filter_or_exclude
    clone._filter_or_exclude_inplace(negate, args, kwargs)
  File "/home/nando/prog/finper/vfinper/lib/python3.8/site-packages/django/db/models/query.py", line 968, in _filter_or_exclude_inplace
    self._query.add_q(Q(*args, **kwargs))
  File "/home/nando/prog/finper/vfinper/lib/python3.8/site-packages/django/db/models/sql/query.py", line 1396, in add_q
    clause, _ = self._add_q(q_object, self.used_aliases)
  File "/home/nando/prog/finper/vfinper/lib/python3.8/site-packages/django/db/models/sql/query.py", line 1415, in _add_q
    child_clause, needed_inner = self.build_filter(
  File "/home/nando/prog/finper/vfinper/lib/python3.8/site-packages/django/db/models/sql/query.py", line 1289, in build_filter
    lookups, parts, reffed_expression = self.solve_lookup_type(arg)
  File "/home/nando/prog/finper/vfinper/lib/python3.8/site-packages/django/db/models/sql/query.py", line 1115, in solve_lookup_type
    _, field, _, lookup_parts = self.names_to_path(lookup_splitted, self.get_meta())
  File "/home/nando/prog/finper/vfinper/lib/python3.8/site-packages/django/db/models/sql/query.py", line 1542, in names_to_path
    raise FieldError("Cannot resolve keyword '%s' into field. "
django.core.exceptions.FieldError: Cannot resolve keyword 'fecha' into field. Choices are: cuenta, cuenta_id, id, importe, movimiento, movimiento_id

======================================================================
ERROR: test_segundo_registro_de_cuenta_en_fecha_no_genera_nuevo_saldo (tests.diario.test_models.test_saldo.TestSaldoMetodoRegistrar)
----------------------------------------------------------------------
Traceback (most recent call last):
  File "/home/nando/prog/finper/tests/diario/test_models/test_saldo.py", line 234, in test_segundo_registro_de_cuenta_en_fecha_no_genera_nuevo_saldo
    Saldo.registrar(self.cuenta, date(2010, 11, 11), 100)
  File "/home/nando/prog/finper/diario/models/saldo.py", line 86, in registrar
    saldo = super().tomar(cuenta=cuenta, fecha=fecha)
  File "/home/nando/prog/finper/vvmodel/models.py", line 29, in tomar
    return cls.objects.db_manager(using).get(**kwargs)
  File "/home/nando/prog/finper/vfinper/lib/python3.8/site-packages/django/db/models/manager.py", line 85, in manager_method
    return getattr(self.get_queryset(), name)(*args, **kwargs)
  File "/home/nando/prog/finper/vfinper/lib/python3.8/site-packages/django/db/models/query.py", line 424, in get
    clone = self._chain() if self.query.combinator else self.filter(*args, **kwargs)
  File "/home/nando/prog/finper/vfinper/lib/python3.8/site-packages/django/db/models/query.py", line 941, in filter
    return self._filter_or_exclude(False, args, kwargs)
  File "/home/nando/prog/finper/vfinper/lib/python3.8/site-packages/django/db/models/query.py", line 961, in _filter_or_exclude
    clone._filter_or_exclude_inplace(negate, args, kwargs)
  File "/home/nando/prog/finper/vfinper/lib/python3.8/site-packages/django/db/models/query.py", line 968, in _filter_or_exclude_inplace
    self._query.add_q(Q(*args, **kwargs))
  File "/home/nando/prog/finper/vfinper/lib/python3.8/site-packages/django/db/models/sql/query.py", line 1396, in add_q
    clause, _ = self._add_q(q_object, self.used_aliases)
  File "/home/nando/prog/finper/vfinper/lib/python3.8/site-packages/django/db/models/sql/query.py", line 1415, in _add_q
    child_clause, needed_inner = self.build_filter(
  File "/home/nando/prog/finper/vfinper/lib/python3.8/site-packages/django/db/models/sql/query.py", line 1289, in build_filter
    lookups, parts, reffed_expression = self.solve_lookup_type(arg)
  File "/home/nando/prog/finper/vfinper/lib/python3.8/site-packages/django/db/models/sql/query.py", line 1115, in solve_lookup_type
    _, field, _, lookup_parts = self.names_to_path(lookup_splitted, self.get_meta())
  File "/home/nando/prog/finper/vfinper/lib/python3.8/site-packages/django/db/models/sql/query.py", line 1542, in names_to_path
    raise FieldError("Cannot resolve keyword '%s' into field. "
django.core.exceptions.FieldError: Cannot resolve keyword 'fecha' into field. Choices are: cuenta, cuenta_id, id, importe, movimiento, movimiento_id

======================================================================
ERROR: test_segundo_registro_de_otra_cuenta_en_fecha_genera_nuevo_saldo (tests.diario.test_models.test_saldo.TestSaldoMetodoRegistrar)
----------------------------------------------------------------------
Traceback (most recent call last):
  File "/home/nando/prog/finper/tests/diario/test_models/test_saldo.py", line 242, in test_segundo_registro_de_otra_cuenta_en_fecha_genera_nuevo_saldo
    Saldo.registrar(self.cuenta, date(2010, 11, 11), 10)
  File "/home/nando/prog/finper/diario/models/saldo.py", line 86, in registrar
    saldo = super().tomar(cuenta=cuenta, fecha=fecha)
  File "/home/nando/prog/finper/vvmodel/models.py", line 29, in tomar
    return cls.objects.db_manager(using).get(**kwargs)
  File "/home/nando/prog/finper/vfinper/lib/python3.8/site-packages/django/db/models/manager.py", line 85, in manager_method
    return getattr(self.get_queryset(), name)(*args, **kwargs)
  File "/home/nando/prog/finper/vfinper/lib/python3.8/site-packages/django/db/models/query.py", line 424, in get
    clone = self._chain() if self.query.combinator else self.filter(*args, **kwargs)
  File "/home/nando/prog/finper/vfinper/lib/python3.8/site-packages/django/db/models/query.py", line 941, in filter
    return self._filter_or_exclude(False, args, kwargs)
  File "/home/nando/prog/finper/vfinper/lib/python3.8/site-packages/django/db/models/query.py", line 961, in _filter_or_exclude
    clone._filter_or_exclude_inplace(negate, args, kwargs)
  File "/home/nando/prog/finper/vfinper/lib/python3.8/site-packages/django/db/models/query.py", line 968, in _filter_or_exclude_inplace
    self._query.add_q(Q(*args, **kwargs))
  File "/home/nando/prog/finper/vfinper/lib/python3.8/site-packages/django/db/models/sql/query.py", line 1396, in add_q
    clause, _ = self._add_q(q_object, self.used_aliases)
  File "/home/nando/prog/finper/vfinper/lib/python3.8/site-packages/django/db/models/sql/query.py", line 1415, in _add_q
    child_clause, needed_inner = self.build_filter(
  File "/home/nando/prog/finper/vfinper/lib/python3.8/site-packages/django/db/models/sql/query.py", line 1289, in build_filter
    lookups, parts, reffed_expression = self.solve_lookup_type(arg)
  File "/home/nando/prog/finper/vfinper/lib/python3.8/site-packages/django/db/models/sql/query.py", line 1115, in solve_lookup_type
    _, field, _, lookup_parts = self.names_to_path(lookup_splitted, self.get_meta())
  File "/home/nando/prog/finper/vfinper/lib/python3.8/site-packages/django/db/models/sql/query.py", line 1542, in names_to_path
    raise FieldError("Cannot resolve keyword '%s' into field. "
django.core.exceptions.FieldError: Cannot resolve keyword 'fecha' into field. Choices are: cuenta, cuenta_id, id, importe, movimiento, movimiento_id

======================================================================
ERROR: test_segundo_registro_en_fecha_antigua_modifica_saldos_de_fechas_posteriores (tests.diario.test_models.test_saldo.TestSaldoMetodoRegistrar)
----------------------------------------------------------------------
Traceback (most recent call last):
  File "/home/nando/prog/finper/tests/diario/test_models/test_saldo.py", line 281, in test_segundo_registro_en_fecha_antigua_modifica_saldos_de_fechas_posteriores
    Saldo.registrar(self.cuenta, date(2010, 11, 11), 30)
  File "/home/nando/prog/finper/diario/models/saldo.py", line 86, in registrar
    saldo = super().tomar(cuenta=cuenta, fecha=fecha)
  File "/home/nando/prog/finper/vvmodel/models.py", line 29, in tomar
    return cls.objects.db_manager(using).get(**kwargs)
  File "/home/nando/prog/finper/vfinper/lib/python3.8/site-packages/django/db/models/manager.py", line 85, in manager_method
    return getattr(self.get_queryset(), name)(*args, **kwargs)
  File "/home/nando/prog/finper/vfinper/lib/python3.8/site-packages/django/db/models/query.py", line 424, in get
    clone = self._chain() if self.query.combinator else self.filter(*args, **kwargs)
  File "/home/nando/prog/finper/vfinper/lib/python3.8/site-packages/django/db/models/query.py", line 941, in filter
    return self._filter_or_exclude(False, args, kwargs)
  File "/home/nando/prog/finper/vfinper/lib/python3.8/site-packages/django/db/models/query.py", line 961, in _filter_or_exclude
    clone._filter_or_exclude_inplace(negate, args, kwargs)
  File "/home/nando/prog/finper/vfinper/lib/python3.8/site-packages/django/db/models/query.py", line 968, in _filter_or_exclude_inplace
    self._query.add_q(Q(*args, **kwargs))
  File "/home/nando/prog/finper/vfinper/lib/python3.8/site-packages/django/db/models/sql/query.py", line 1396, in add_q
    clause, _ = self._add_q(q_object, self.used_aliases)
  File "/home/nando/prog/finper/vfinper/lib/python3.8/site-packages/django/db/models/sql/query.py", line 1415, in _add_q
    child_clause, needed_inner = self.build_filter(
  File "/home/nando/prog/finper/vfinper/lib/python3.8/site-packages/django/db/models/sql/query.py", line 1289, in build_filter
    lookups, parts, reffed_expression = self.solve_lookup_type(arg)
  File "/home/nando/prog/finper/vfinper/lib/python3.8/site-packages/django/db/models/sql/query.py", line 1115, in solve_lookup_type
    _, field, _, lookup_parts = self.names_to_path(lookup_splitted, self.get_meta())
  File "/home/nando/prog/finper/vfinper/lib/python3.8/site-packages/django/db/models/sql/query.py", line 1542, in names_to_path
    raise FieldError("Cannot resolve keyword '%s' into field. "
django.core.exceptions.FieldError: Cannot resolve keyword 'fecha' into field. Choices are: cuenta, cuenta_id, id, importe, movimiento, movimiento_id

======================================================================
ERROR: test_segundo_registro_en_fecha_suma_importe_a_saldo (tests.diario.test_models.test_saldo.TestSaldoMetodoRegistrar)
----------------------------------------------------------------------
Traceback (most recent call last):
  File "/home/nando/prog/finper/tests/diario/test_models/test_saldo.py", line 248, in test_segundo_registro_en_fecha_suma_importe_a_saldo
    Saldo.registrar(self.cuenta, date(2010, 11, 11), 10)
  File "/home/nando/prog/finper/diario/models/saldo.py", line 86, in registrar
    saldo = super().tomar(cuenta=cuenta, fecha=fecha)
  File "/home/nando/prog/finper/vvmodel/models.py", line 29, in tomar
    return cls.objects.db_manager(using).get(**kwargs)
  File "/home/nando/prog/finper/vfinper/lib/python3.8/site-packages/django/db/models/manager.py", line 85, in manager_method
    return getattr(self.get_queryset(), name)(*args, **kwargs)
  File "/home/nando/prog/finper/vfinper/lib/python3.8/site-packages/django/db/models/query.py", line 424, in get
    clone = self._chain() if self.query.combinator else self.filter(*args, **kwargs)
  File "/home/nando/prog/finper/vfinper/lib/python3.8/site-packages/django/db/models/query.py", line 941, in filter
    return self._filter_or_exclude(False, args, kwargs)
  File "/home/nando/prog/finper/vfinper/lib/python3.8/site-packages/django/db/models/query.py", line 961, in _filter_or_exclude
    clone._filter_or_exclude_inplace(negate, args, kwargs)
  File "/home/nando/prog/finper/vfinper/lib/python3.8/site-packages/django/db/models/query.py", line 968, in _filter_or_exclude_inplace
    self._query.add_q(Q(*args, **kwargs))
  File "/home/nando/prog/finper/vfinper/lib/python3.8/site-packages/django/db/models/sql/query.py", line 1396, in add_q
    clause, _ = self._add_q(q_object, self.used_aliases)
  File "/home/nando/prog/finper/vfinper/lib/python3.8/site-packages/django/db/models/sql/query.py", line 1415, in _add_q
    child_clause, needed_inner = self.build_filter(
  File "/home/nando/prog/finper/vfinper/lib/python3.8/site-packages/django/db/models/sql/query.py", line 1289, in build_filter
    lookups, parts, reffed_expression = self.solve_lookup_type(arg)
  File "/home/nando/prog/finper/vfinper/lib/python3.8/site-packages/django/db/models/sql/query.py", line 1115, in solve_lookup_type
    _, field, _, lookup_parts = self.names_to_path(lookup_splitted, self.get_meta())
  File "/home/nando/prog/finper/vfinper/lib/python3.8/site-packages/django/db/models/sql/query.py", line 1542, in names_to_path
    raise FieldError("Cannot resolve keyword '%s' into field. "
django.core.exceptions.FieldError: Cannot resolve keyword 'fecha' into field. Choices are: cuenta, cuenta_id, id, importe, movimiento, movimiento_id

======================================================================
ERROR: test_si_cuenta_tiene_cuenta_abuela_registra_saldo_en_fecha_en_cuenta_abuela (tests.diario.test_models.test_saldo.TestSaldoMetodoRegistrar)
----------------------------------------------------------------------
Traceback (most recent call last):
  File "/usr/lib/python3.8/unittest/mock.py", line 1325, in patched
    return func(*newargs, **newkeywargs)
  File "/home/nando/prog/finper/tests/diario/test_models/test_saldo.py", line 348, in test_si_cuenta_tiene_cuenta_abuela_registra_saldo_en_fecha_en_cuenta_abuela
    Saldo.registrar(sc1_1, date(2010, 11, 11), 30)
  File "/home/nando/prog/finper/diario/models/saldo.py", line 86, in registrar
    saldo = super().tomar(cuenta=cuenta, fecha=fecha)
  File "/home/nando/prog/finper/vvmodel/models.py", line 29, in tomar
    return cls.objects.db_manager(using).get(**kwargs)
  File "/home/nando/prog/finper/vfinper/lib/python3.8/site-packages/django/db/models/manager.py", line 85, in manager_method
    return getattr(self.get_queryset(), name)(*args, **kwargs)
  File "/home/nando/prog/finper/vfinper/lib/python3.8/site-packages/django/db/models/query.py", line 424, in get
    clone = self._chain() if self.query.combinator else self.filter(*args, **kwargs)
  File "/home/nando/prog/finper/vfinper/lib/python3.8/site-packages/django/db/models/query.py", line 941, in filter
    return self._filter_or_exclude(False, args, kwargs)
  File "/home/nando/prog/finper/vfinper/lib/python3.8/site-packages/django/db/models/query.py", line 961, in _filter_or_exclude
    clone._filter_or_exclude_inplace(negate, args, kwargs)
  File "/home/nando/prog/finper/vfinper/lib/python3.8/site-packages/django/db/models/query.py", line 968, in _filter_or_exclude_inplace
    self._query.add_q(Q(*args, **kwargs))
  File "/home/nando/prog/finper/vfinper/lib/python3.8/site-packages/django/db/models/sql/query.py", line 1396, in add_q
    clause, _ = self._add_q(q_object, self.used_aliases)
  File "/home/nando/prog/finper/vfinper/lib/python3.8/site-packages/django/db/models/sql/query.py", line 1415, in _add_q
    child_clause, needed_inner = self.build_filter(
  File "/home/nando/prog/finper/vfinper/lib/python3.8/site-packages/django/db/models/sql/query.py", line 1289, in build_filter
    lookups, parts, reffed_expression = self.solve_lookup_type(arg)
  File "/home/nando/prog/finper/vfinper/lib/python3.8/site-packages/django/db/models/sql/query.py", line 1115, in solve_lookup_type
    _, field, _, lookup_parts = self.names_to_path(lookup_splitted, self.get_meta())
  File "/home/nando/prog/finper/vfinper/lib/python3.8/site-packages/django/db/models/sql/query.py", line 1542, in names_to_path
    raise FieldError("Cannot resolve keyword '%s' into field. "
django.core.exceptions.FieldError: Cannot resolve keyword 'fecha' into field. Choices are: cuenta, cuenta_id, id, importe, movimiento, movimiento_id

======================================================================
ERROR: test_si_cuenta_tiene_cuenta_madre_registra_saldo_en_fecha_en_cuenta_madre (tests.diario.test_models.test_saldo.TestSaldoMetodoRegistrar)
----------------------------------------------------------------------
Traceback (most recent call last):
  File "/usr/lib/python3.8/unittest/mock.py", line 1325, in patched
    return func(*newargs, **newkeywargs)
  File "/home/nando/prog/finper/tests/diario/test_models/test_saldo.py", line 314, in test_si_cuenta_tiene_cuenta_madre_registra_saldo_en_fecha_en_cuenta_madre
    Saldo.registrar(sc1, date(2010, 11, 11), 30)
  File "/home/nando/prog/finper/diario/models/saldo.py", line 86, in registrar
    saldo = super().tomar(cuenta=cuenta, fecha=fecha)
  File "/home/nando/prog/finper/vvmodel/models.py", line 29, in tomar
    return cls.objects.db_manager(using).get(**kwargs)
  File "/home/nando/prog/finper/vfinper/lib/python3.8/site-packages/django/db/models/manager.py", line 85, in manager_method
    return getattr(self.get_queryset(), name)(*args, **kwargs)
  File "/home/nando/prog/finper/vfinper/lib/python3.8/site-packages/django/db/models/query.py", line 424, in get
    clone = self._chain() if self.query.combinator else self.filter(*args, **kwargs)
  File "/home/nando/prog/finper/vfinper/lib/python3.8/site-packages/django/db/models/query.py", line 941, in filter
    return self._filter_or_exclude(False, args, kwargs)
  File "/home/nando/prog/finper/vfinper/lib/python3.8/site-packages/django/db/models/query.py", line 961, in _filter_or_exclude
    clone._filter_or_exclude_inplace(negate, args, kwargs)
  File "/home/nando/prog/finper/vfinper/lib/python3.8/site-packages/django/db/models/query.py", line 968, in _filter_or_exclude_inplace
    self._query.add_q(Q(*args, **kwargs))
  File "/home/nando/prog/finper/vfinper/lib/python3.8/site-packages/django/db/models/sql/query.py", line 1396, in add_q
    clause, _ = self._add_q(q_object, self.used_aliases)
  File "/home/nando/prog/finper/vfinper/lib/python3.8/site-packages/django/db/models/sql/query.py", line 1415, in _add_q
    child_clause, needed_inner = self.build_filter(
  File "/home/nando/prog/finper/vfinper/lib/python3.8/site-packages/django/db/models/sql/query.py", line 1289, in build_filter
    lookups, parts, reffed_expression = self.solve_lookup_type(arg)
  File "/home/nando/prog/finper/vfinper/lib/python3.8/site-packages/django/db/models/sql/query.py", line 1115, in solve_lookup_type
    _, field, _, lookup_parts = self.names_to_path(lookup_splitted, self.get_meta())
  File "/home/nando/prog/finper/vfinper/lib/python3.8/site-packages/django/db/models/sql/query.py", line 1542, in names_to_path
    raise FieldError("Cannot resolve keyword '%s' into field. "
django.core.exceptions.FieldError: Cannot resolve keyword 'fecha' into field. Choices are: cuenta, cuenta_id, id, importe, movimiento, movimiento_id

----------------------------------------------------------------------
Ran 30 tests in 1.052s

FAILED (errors=10)
Destroying test database for alias 'default'...
